<?xml version="1.0" ?>
<!-- =================================================================================== -->
<!-- |    This document was autogenerated by xacro from sia20_goelz.urdf.xacro         | -->
<!-- |    EDITING THIS FILE BY HAND IS NOT RECOMMENDED                                 | -->
<!-- =================================================================================== -->
<robot name="sia20_goelz" xmlns:xacro="http://ros.org/wiki/xacro">
  <material name="blue">
    <color rgba="0 0 1 1"/>
  </material>
  <material name="yellow">
    <color rgba="0 1 1 1"/>
  </material>
  <material name="silver">
    <color rgba="0.8 0.8 0.8 1"/>
  </material>
  <!-- link list -->
  <link name="saw_base_link">
    <visual>
      <geometry>
        <mesh filename="package://motoman_sia20d_support/meshes/sia20d/visual/MOTOMAN_BASE.stl"/>
      </geometry>
      <material name="blue"/>
    </visual>
    <collision>
      <geometry>
        <mesh filename="package://motoman_sia20d_support/meshes/sia20d/collision/MOTOMAN_BASE.stl"/>
      </geometry>
    </collision>
    <inertial>
      <mass value="40.24"/>
      <origin rpy="0 0 0" xyz="0 0 0"/>
      <inertia ixx="0.0" ixy="0.0" ixz="0.0" iyy="1.831" iyz="0.0" izz="-6.237"/>
    </inertial>
  </link>
  <link name="saw_link_s">
    <visual>
      <origin rpy="0 0 3.1416" xyz="0 0 0"/>
      <geometry>
        <mesh filename="package://motoman_sia20d_support/meshes/sia20d/visual/MOTOMAN_AXIS_S.stl"/>
      </geometry>
      <material name="silver"/>
    </visual>
    <collision>
      <origin rpy="0 0 3.1416" xyz="0 0 0"/>
      <geometry>
        <mesh filename="package://motoman_sia20d_support/meshes/sia20d/collision/MOTOMAN_AXIS_S.stl"/>
      </geometry>
      <material name="yellow"/>
    </collision>
    <inertial>
      <mass value="40.24"/>
      <origin rpy="0 0 0" xyz="0 0.045 -0.155"/>
      <inertia ixx="0.0" ixy="0.0" ixz="0.0" iyy="1.831" iyz="0.0" izz="-6.237"/>
    </inertial>
  </link>
  <link name="saw_link_l">
    <visual>
      <origin rpy="1.57 3.1416 3.1416" xyz="0 0 0"/>
      <geometry>
        <mesh filename="package://motoman_sia20d_support/meshes/sia20d/visual/MOTOMAN_AXIS_L.stl"/>
      </geometry>
      <material name="blue"/>
    </visual>
    <collision>
      <origin rpy="1.57 3.1416 3.1416" xyz="0 0 0"/>
      <geometry>
        <mesh filename="package://motoman_sia20d_support/meshes/sia20d/collision/MOTOMAN_AXIS_L.stl"/>
      </geometry>
      <material name="yellow"/>
    </collision>
    <inertial>
      <mass value="15.54"/>
      <origin rpy="0 0 0" xyz="0.1472 0 0.0174"/>
      <inertia ixx="2.2287" ixy="0.0" ixz="0.0" iyy="0.0" iyz="0.0" izz="0.27"/>
    </inertial>
  </link>
  <link name="saw_link_e">
    <visual>
      <origin rpy="0 0 0" xyz="0 0 0"/>
      <geometry>
        <mesh filename="package://motoman_sia20d_support/meshes/sia20d/visual/MOTOMAN_AXIS_E.stl"/>
      </geometry>
      <material name="silver"/>
    </visual>
    <collision>
      <origin rpy="0 0 0" xyz="0 0 0"/>
      <geometry>
        <mesh filename="package://motoman_sia20d_support/meshes/sia20d/collision/MOTOMAN_AXIS_E.stl"/>
      </geometry>
      <material name="yellow"/>
    </collision>
    <inertial>
      <mass value="13.96"/>
      <origin rpy="0 0 0" xyz="0.0073 -0.0049 -0.0412"/>
      <inertia ixx="0.102" ixy="0.0" ixz="0.0" iyy="-0.068" iyz="0.0" izz="-0.575"/>
    </inertial>
  </link>
  <link name="saw_link_u">
    <visual>
      <origin rpy="1.57 -3.1415 3.1416" xyz="0 0 0"/>
      <geometry>
        <mesh filename="package://motoman_sia20d_support/meshes/sia20d/visual/MOTOMAN_AXIS_U.stl"/>
      </geometry>
      <material name="blue"/>
    </visual>
    <collision>
      <origin rpy="1.57 -3.1415 3.1416" xyz="0 0 0"/>
      <geometry>
        <mesh filename="package://motoman_sia20d_support/meshes/sia20d/collision/MOTOMAN_AXIS_U.stl"/>
      </geometry>
      <material name="yellow"/>
    </collision>
    <inertial>
      <mass value="7.076"/>
      <origin rpy="0 0 0" xyz="0.0 -0.1427 -0.0018"/>
      <inertia ixx="-0.002" ixy="0.0" ixz="0.0" iyy="-1.01" iyz="0.0" izz="-0.013"/>
    </inertial>
  </link>
  <link name="saw_link_r">
    <visual>
      <origin rpy="0 0 0" xyz="0 0 0"/>
      <geometry>
        <mesh filename="package://motoman_sia20d_support/meshes/sia20d/visual/MOTOMAN_AXIS_R.stl"/>
      </geometry>
      <material name="silver"/>
    </visual>
    <collision>
      <origin rpy="0 0 0" xyz="0 0 0"/>
      <geometry>
        <mesh filename="package://motoman_sia20d_support/meshes/sia20d/collision/MOTOMAN_AXIS_R.stl"/>
      </geometry>
      <material name="yellow"/>
    </collision>
    <inertial>
      <mass value="5.532"/>
      <origin rpy="0 0 0" xyz="0 -0.0973 0.0081"/>
      <inertia ixx="0.0" ixy="0.0" ixz="0.0" iyy="-0.227" iyz="0.0" izz="-0.24"/>
    </inertial>
  </link>
  <link name="saw_link_b">
    <visual>
      <origin rpy="-1.57 0 0" xyz="0 0 0"/>
      <geometry>
        <mesh filename="package://motoman_sia20d_support/meshes/sia20d/visual/MOTOMAN_AXIS_B.stl"/>
      </geometry>
      <material name="blue"/>
    </visual>
    <collision>
      <origin rpy="-1.57 0 0" xyz="0 0 0"/>
      <geometry>
        <mesh filename="package://motoman_sia20d_support/meshes/sia20d/collision/MOTOMAN_AXIS_B.stl"/>
      </geometry>
      <material name="yellow"/>
    </collision>
    <inertial>
      <mass value="4.840"/>
      <origin rpy="0 0 0" xyz="0 0 -0.005"/>
      <inertia ixx="0.066" ixy="0.0" ixz="0.0" iyy="0.011" iyz="0.0" izz="0.066"/>
    </inertial>
  </link>
  <link name="saw_link_t">
    <visual>
      <geometry>
        <mesh filename="package://motoman_sia20d_support/meshes/sia20d/visual/MOTOMAN_AXIS_T.stl"/>
      </geometry>
      <material name="silver"/>
    </visual>
    <collision>
      <geometry>
        <mesh filename="package://motoman_sia20d_support/meshes/sia20d/collision/MOTOMAN_AXIS_T.stl"/>
      </geometry>
      <material name="yellow"/>
    </collision>
    <inertial>
      <mass value="0.523"/>
      <origin rpy="0 0 0" xyz="0 0 -0.005"/>
      <inertia ixx="0" ixy="0.0" ixz="0.0" iyy="0" iyz="0.0" izz="-0.003"/>
    </inertial>
  </link>
  <link name="saw_tool0"/>
  <!-- end of link list -->
  <!-- joint list -->
  <joint name="saw_joint_s" type="revolute">
    <parent link="saw_base_link"/>
    <child link="saw_link_s"/>
    <origin rpy="0 0 0" xyz="0 0 0.41"/>
    <axis xyz="0 0 1"/>
    <limit effort="100" lower="-3.07867" upper="3.07867" velocity="2.2689"/>
  </joint>
  <joint name="saw_joint_l" type="revolute">
    <parent link="saw_link_s"/>
    <child link="saw_link_l"/>
    <origin rpy="0 0 0" xyz="0 0 0"/>
    <axis xyz="0 1 0"/>
    <limit effort="100" lower="-1.8814039" upper="1.8814039" velocity="2.2689"/>
  </joint>
  <joint name="saw_joint_e" type="revolute">
    <parent link="saw_link_l"/>
    <child link="saw_link_e"/>
    <origin rpy="0 0 0" xyz="0 0 0.49"/>
    <axis xyz="0 0 1"/>
    <limit effort="100" lower="-2.90766" upper="2.90766" velocity="2.9670"/>
  </joint>
  <joint name="saw_joint_u" type="revolute">
    <parent link="saw_link_e"/>
    <child link="saw_link_u"/>
    <origin rpy="0 0 0" xyz="0 0 0"/>
    <axis xyz="0 -1 0"/>
    <limit effort="100" lower="-2.223522" upper="2.223522" velocity="2.9670"/>
  </joint>
  <joint name="saw_joint_r" type="revolute">
    <parent link="saw_link_u"/>
    <child link="saw_link_r"/>
    <origin rpy="0 0 0" xyz="0 0 0.420"/>
    <axis xyz="0 0 -1"/>
    <limit effort="100" lower="-2.9547" upper="2.9547" velocity="3.4906"/>
  </joint>
  <joint name="saw_joint_b" type="revolute">
    <parent link="saw_link_r"/>
    <child link="saw_link_b"/>
    <origin rpy="0 0 0" xyz="0 0 0"/>
    <axis xyz="0 -1 0"/>
    <limit effort="100" lower="-1.8814" upper="1.8814" velocity="3.4906"/>
  </joint>
  <joint name="saw_joint_t" type="revolute">
    <parent link="saw_link_b"/>
    <child link="saw_link_t"/>
    <origin rpy="0 0 0" xyz="0 0 0.18"/>
    <axis xyz="0 0 -1"/>
    <limit effort="100" lower="-3.07867" upper="3.07867" velocity="6.9813"/>
  </joint>
  <joint name="saw_link_t-tool0" type="fixed">
    <origin rpy="0 0 -3.1415926535" xyz="0 0 0.0"/>
    <parent link="saw_link_t"/>
    <child link="saw_tool0"/>
  </joint>
  <!-- end of joint list -->
  <transmission name="saw_shoulder_pan_trans">
    <type>transmission_interface/SimpleTransmission</type>
    <joint name="saw_joint_s">
      <hardwareInterface>hardware_interface/PositionJointInterface</hardwareInterface>
    </joint>
    <actuator name="saw_shoulder_pan_motor">
      <mechanicalReduction>1</mechanicalReduction>
    </actuator>
  </transmission>
  <transmission name="saw_shoulder_lift_trans">
    <type>transmission_interface/SimpleTransmission</type>
    <joint name="saw_joint_l">
      <hardwareInterface>hardware_interface/PositionJointInterface</hardwareInterface>
    </joint>
    <actuator name="saw_shoulder_lift_motor">
      <mechanicalReduction>1</mechanicalReduction>
    </actuator>
  </transmission>
  <transmission name="saw_elbow_trans">
    <type>transmission_interface/SimpleTransmission</type>
    <joint name="saw_joint_e">
      <hardwareInterface>hardware_interface/PositionJointInterface</hardwareInterface>
    </joint>
    <actuator name="saw_elbow_motor">
      <mechanicalReduction>1</mechanicalReduction>
    </actuator>
  </transmission>
  <transmission name="saw_wrist_1_trans">
    <type>transmission_interface/SimpleTransmission</type>
    <joint name="saw_joint_u">
      <hardwareInterface>hardware_interface/PositionJointInterface</hardwareInterface>
    </joint>
    <actuator name="saw_wrist_1_motor">
      <mechanicalReduction>1</mechanicalReduction>
    </actuator>
  </transmission>
  <transmission name="saw_wrist_2_trans">
    <type>transmission_interface/SimpleTransmission</type>
    <joint name="saw_joint_r">
      <hardwareInterface>hardware_interface/PositionJointInterface</hardwareInterface>
    </joint>
    <actuator name="saw_wrist_2_motor">
      <mechanicalReduction>1</mechanicalReduction>
    </actuator>
  </transmission>
  <transmission name="saw_wrist_3_trans">
    <type>transmission_interface/SimpleTransmission</type>
    <joint name="saw_joint_b">
      <hardwareInterface>hardware_interface/PositionJointInterface</hardwareInterface>
    </joint>
    <actuator name="saw_wrist_3_motor">
      <mechanicalReduction>1</mechanicalReduction>
    </actuator>
  </transmission>
  <transmission name="saw_wrist_4_trans">
    <type>transmission_interface/SimpleTransmission</type>
    <joint name="saw_joint_t">
      <hardwareInterface>hardware_interface/PositionJointInterface</hardwareInterface>
    </joint>
    <actuator name="saw_wrist_4_motor">
      <mechanicalReduction>1</mechanicalReduction>
    </actuator>
  </transmission>
  <gazebo reference="saw_link_s">
    <selfCollide>true</selfCollide>
  </gazebo>
  <gazebo reference="saw_link_l">
    <selfCollide>true</selfCollide>
  </gazebo>
  <gazebo reference="saw_link_e">
    <selfCollide>true</selfCollide>
  </gazebo>
  <gazebo reference="saw_link_u">
    <selfCollide>true</selfCollide>
  </gazebo>
  <gazebo reference="saw_link_r">
    <selfCollide>true</selfCollide>
  </gazebo>
  <gazebo reference="saw_link_b">
    <selfCollide>true</selfCollide>
  </gazebo>
  <gazebo reference="saw_link_t">
    <selfCollide>true</selfCollide>
  </gazebo>
  <!-- ROS base_link (via base_link) to Motoman Robot (not Base) Frame transform -->
  <link name="saw_base"/>
  <!--<joint name="${prefix}base_link-base" type="fixed">
			<origin xyz="0 0 0.410" rpy="0 0 0"/>
			<parent link="${prefix}base_link"/>
			<child link="${prefix}base"/>
		</joint> -->
  <joint name="base_link-base_fixed_joint" type="fixed">
    <!-- NOTE: this rotation is only needed as long as base_link itself is
						not corrected wrt the real robot (ie: rotated over 180
						degrees)
			-->
    <origin rpy="-1.5707963267948966 0.0 1.5707963267948966" xyz="0 0 0"/>
    <parent link="saw_base"/>
    <child link="saw_base_link"/>
  </joint>
  <gazebo reference="saw_base_link">
    <material>Gazebo/Blue</material>
  </gazebo>
  <gazebo reference="saw_link_s">
    <material>Gazebo/DarkGrey </material>
  </gazebo>
  <gazebo reference="saw_link_l">
    <material>Gazebo/Blue</material>
  </gazebo>
  <gazebo reference="saw_link_e">
    <material>Gazebo/DarkGrey </material>
  </gazebo>
  <gazebo reference="saw_link_u">
    <material>Gazebo/Blue</material>
  </gazebo>
  <gazebo reference="saw_link_r">
    <material>Gazebo/DarkGrey </material>
  </gazebo>
  <gazebo reference="saw_link_b">
    <material>Gazebo/Blue</material>
  </gazebo>
  <gazebo reference="saw_link_t">
    <material>Gazebo/DarkGrey </material>
  </gazebo>
  <material name="silver2">
    <color rgba="0.8 0.8 0.8 1"/>
  </material>
  <link name="saw_link">
    <visual name="visual">
      <geometry>
        <cylinder length="0.005" radius="0.20"/>
      </geometry>
      <!-- <origin xyz="-0.0 0.138 0.04" rpy="1.57 0 0" /> -->
      <origin rpy="0 0 0" xyz="0 0 0"/>
      <material name="silver2"/>
    </visual>
    <collision>
      <geometry>
        <cylinder length="0.005" radius="0.22"/>
      </geometry>
      <!-- <origin xyz="-0.0 0.138 0.04" rpy="1.57 0 0" /> -->
      <origin rpy="0 0 0" xyz="0 0 0"/>
      <material name="silver2"/>
    </collision>
  </link>
  <!-- <link name="${prefix}guard_link">
      <visual name='visual'>
        <geometry>
        <mesh filename="package://bot_digger_description/meshes/GoelzArmConfig.STL" scale="1.0 1.0 1.0"/>          
        </geometry>
     
      <origin xyz="-0.083 -0.15 -0.397" rpy="0 0 0" /> 
      </visual>
      <collision>
        <geometry>    
           <mesh filename="package://bot_digger_description/meshes/GoelzArmConfig.STL" scale="1.0 1.0 1.0"/>
        </geometry>

        <origin xyz="-0.083 -0.15 -0.397" rpy="0 0 0" /> 
      </collision>
    </link> -->
  <link name="saw_guard_link">
    <visual name="visual">
      <geometry>
        <mesh filename="package://bot_digger_description/meshes/201007GoelzArmConfig_UNIfix.STL" scale="1.0 1.0 1.0"/>
      </geometry>
    </visual>
    <collision>
      <geometry>
        <mesh filename="package://bot_digger_description/meshes/201007GoelzArmConfig_UNIfix.STL" scale="1.0 1.0 1.0"/>
      </geometry>
    </collision>
  </link>
  <!-- attachment between saw_link (blade) and tool0 -->
  <!-- <joint name="${prefix}blade_joint" type="fixed">
      <parent link = "${prefix}tool0" />
      <child link="${prefix}link" /> -->
  <!-- <origin xyz="0.0 0.0 0.0" rpy="0.0 0.0 0.0" /> -->
  <!-- <origin xyz="0 0 0.08" rpy="0.00 0.0 2.64" />    rz = -0.45? -->
  <!-- </joint> -->
  <!-- attachment between saw_link (blade) and tool0 (1/14) -->
  <joint name="saw_blade_joint" type="fixed">
    <parent link="saw_tip_link"/>
    <child link="saw_link"/>
    <!-- <origin xyz="0.0 0.0 0.0" rpy="0.0 0.0 0.0" /> -->
    <origin rpy="0.00 1.57 0.00" xyz="-0.000 0 0.00"/>
    <!-- rz = -0.45?-->
  </joint>
  <!-- attach to tool0  directions: z-pointed towards tool tip, y is "up", x is "out"-->
  <!-- attachment between saw_guard_link and tool0 -->
  <joint name="saw_fixed_joint" type="fixed">
    <parent link="saw_tool0"/>
    <child link="saw_guard_link"/>
    <!-- <origin xyz="0.0 0.0 0.065" rpy="0.0 0.0 3.14" /> -->
    <origin rpy="0.00 0.0 -2.64" xyz="0.0 0.0 0.0516"/>
    <!-- saw_guard rotation here  3.14 - 0.45-->
  </joint>
  <joint name="saw_tip_fixed_joint" type="fixed">
    <parent link="saw_tool0"/>
    <child link="saw_tip_link"/>
    <origin rpy="-0.010 -0.002 -1.094" xyz="-0.18438 0.038547 0.15145"/>
    <!-- <origin xyz="-0.184 0.041 0.126" rpy="-0.010 -0.002 -1.094"/> Switch back to old TCP orientation calibration Locust Ukam AP#4 -->
  </joint>
  <link name="saw_tip_link">
    <collision>
      <geometry>
        <box size="0.03 0.03 0.03"/>
      </geometry>
      <origin rpy="0 0 0" xyz="0 0 -0.01"/>
      <!-- saw_TCP tf is from saw_tip_link orientation-->
    </collision>
  </link>
  <link name="saw_force_sensor">
    <visual name="visual">
      <geometry>
        <mesh filename="package://bot_digger_description/meshes/200630ATI_assembly.STL" scale="1.0 1.0 1.0"/>
      </geometry>
    </visual>
    <collision>
      <geometry>
        <mesh filename="package://bot_digger_description/meshes/200630ATI_assembly.STL" scale="1.0 1.0 1.0"/>
      </geometry>
    </collision>
  </link>
  <!-- attachment between force_sensor and tool0 -->
  <joint name="saw_sensor_joint" type="fixed">
    <parent link="saw_tool0"/>
    <child link="saw_force_sensor"/>
    <!-- <origin xyz="0.0 0.0 0.065" rpy="0.0 0.0 3.14" /> -->
    <origin rpy="0.0 0.0 -1.0471" xyz="0.0 0.0 0.0084"/>
    <!-- values provided for ATI Force Sensor July12020 -60 deg around tool Z. 51.6mm from saw guard link-->
    <!-- <origin xyz="0.0 0.0 0.030" rpy="0.0 0.0 -0.43633231299858238" />   working values for wacoh sensor Mar32020    25 deg around tool-Z -->
    <!-- <origin xyz="0.0 0.0 0.02" rpy="0.0 0.0 0.327" /> robotiq force sensor 18.75 degrees Mar32020 -->
  </joint>
  <!-- -0.06, 0.06, -0.03 -->
  <!-- </xacro:macro> -->
</robot>
