<?xml version="1.0" ?>
<!-- =================================================================================== -->
<!-- |    This document was autogenerated by xacro from ur16_bosch_openrave.xacro      | -->
<!-- |    EDITING THIS FILE BY HAND IS NOT RECOMMENDED                                 | -->
<!-- =================================================================================== -->
<robot name="or_ur" xmlns:xacro="http://ros.org/wiki/xacro">
  <gazebo>
    <plugin filename="libgazebo_ros_control.so" name="ros_control">
      <!--robotNamespace>/</robotNamespace-->
      <!--robotSimType>gazebo_ros_control/DefaultRobotHWSim</robotSimType-->
    </plugin>
    <!--
    <plugin name="gazebo_ros_power_monitor_controller" filename="libgazebo_ros_power_monitor.so">
      <alwaysOn>true</alwaysOn>
      <updateRate>1.0</updateRate>
      <timeout>5</timeout>
      <powerStateTopic>power_state</powerStateTopic>
      <powerStateRate>10.0</powerStateRate>
      <fullChargeCapacity>87.78</fullChargeCapacity>     
      <dischargeRate>-474</dischargeRate>
      <chargeRate>525</chargeRate>
      <dischargeVoltage>15.52</dischargeVoltage>
      <chargeVoltage>16.41</chargeVoltage>
    </plugin>
-->
  </gazebo>
  <link name="chisel_base_link">
    <inertial>
      <origin rpy="0 0 0" xyz="1.1489E-34 -1.646E-16 0.046885"/>
      <mass value="5.438"/>
      <inertia ixx="0.013275" ixy="8.9258E-35" ixz="3.0589E-20" iyy="0.013275" iyz="-1.5807E-17" izz="0.017725"/>
    </inertial>
    <visual>
      <origin rpy="0 0 0" xyz="0 0 0"/>
      <geometry>
        <mesh filename="package://ur16e_description/meshes/base_link.STL"/>
      </geometry>
      <material name="chisel_">
        <color rgba="0 0.5 0.5 1"/>
      </material>
    </visual>
    <collision>
      <origin rpy="0 0 0" xyz="0 0 0"/>
      <geometry>
        <mesh filename="package://ur16e_description/meshes/base_link.STL"/>
      </geometry>
    </collision>
  </link>
  <link name="chisel_shoulder_link">
    <inertial>
      <origin rpy="0 0 0" xyz="-1.5245E-08 0.012594 0.0014894"/>
      <mass value="9.4377"/>
      <inertia ixx="0.038911" ixy="8.8912E-10" ixz="5.0205E-09" iyy="0.034442" iyz="-0.00033385" izz="0.032728"/>
    </inertial>
    <visual>
      <origin rpy="0 0 0" xyz="0 0 -0.181"/>
      <geometry>
        <mesh filename="package://ur16e_description/meshes/shoulder_link.STL"/>
      </geometry>
      <material name="chisel_">
        <color rgba="0.5 0.5 0.5 1"/>
      </material>
    </visual>
    <collision>
      <origin rpy="0 0 0" xyz="0 0 -0.181"/>
      <geometry>
        <mesh filename="package://ur16e_description/meshes/shoulder_link.STL"/>
      </geometry>
    </collision>
  </link>
  <joint name="chisel_shoulder_pan_joint" type="revolute">
    <origin rpy="0 0 0" xyz="0 0 0.181"/>
    <parent link="chisel_base_link"/>
    <child link="chisel_shoulder_link"/>
    <axis xyz="0 0 1"/>
    <limit effort="150.0" lower="-6.28" upper="6.28" velocity="3.14"/>
  </joint>
  <link name="chisel_upper_arm_link">
    <inertial>
      <origin rpy="0 0 0" xyz="-1.3872E-08 0.00081804 0.18812"/>
      <mass value="22.37"/>
      <inertia ixx="0.78628" ixy="3.8039E-08" ixz="9.7631E-08" iyy="0.77849" iyz="0.002245" izz="0.058581"/>
    </inertial>
    <visual>
      <origin rpy="0 0 0" xyz="0 -0.176 -0.181"/>
      <geometry>
        <mesh filename="package://ur16e_description/meshes/upper_arm_link.STL"/>
      </geometry>
      <material name="chisel_">
        <color rgba="0 0.5 0.5 1"/>
      </material>
    </visual>
    <collision>
      <origin rpy="0 0 0" xyz="0 -0.176 -0.181"/>
      <geometry>
        <mesh filename="package://ur16e_description/meshes/upper_arm_link.STL"/>
      </geometry>
    </collision>
  </link>
  <joint name="chisel_shoulder_lift_joint" type="revolute">
    <origin rpy="0 1.5708 0" xyz="0 0.176 0"/>
    <!-- edited to fix 0 deg config, was 0 0 0  -->
    <parent link="chisel_shoulder_link"/>
    <child link="chisel_upper_arm_link"/>
    <axis xyz="0 1 0"/>
    <limit effort="150.0" lower="-6.28" upper="6.28" velocity="3.14"/>
  </joint>
  <link name="chisel_forearm_link">
    <inertial>
      <origin rpy="0 0 0" xyz="-1.2814E-07 0.0067539 0.16344"/>
      <mass value="9.3652"/>
      <inertia ixx="0.18612" ixy="5.431E-07" ixz="-2.0071E-07" iyy="0.18373" iyz="0.0098497" izz="0.014157"/>
    </inertial>
    <visual>
      <origin rpy="0 0 0" xyz="0 -0.0388 -0.6605"/>
      <geometry>
        <mesh filename="package://ur16e_description/meshes/lower_arm_link.STL"/>
      </geometry>
      <material name="chisel_">
        <color rgba="0.5 0.5 0.5 1"/>
      </material>
    </visual>
    <collision>
      <origin rpy="0 0 0" xyz="0 -0.0388 -0.6605"/>
      <geometry>
        <mesh filename="package://ur16e_description/meshes/lower_arm_link.STL"/>
      </geometry>
    </collision>
  </link>
  <joint name="chisel_elbow_joint" type="revolute">
    <origin rpy="0 0 0" xyz="0 -0.1372 0.4784"/>
    <parent link="chisel_upper_arm_link"/>
    <child link="chisel_forearm_link"/>
    <axis xyz="0 1 0"/>
    <limit effort="150.0" lower="-6.28" upper="6.28" velocity="3.14"/>
  </joint>
  <link name="chisel_wrist_1_link">
    <inertial>
      <origin rpy="0 0 0" xyz="-5.602E-08 0.11949 0.0011483"/>
      <mass value="2.5949"/>
      <inertia ixx="0.0050155" ixy="-6.6962E-10" ixz="-6.2086E-09" iyy="0.0036588" iyz="-0.00010442" izz="0.0041213"/>
    </inertial>
    <visual>
      <origin rpy="0 0 0" xyz="0 -0.0388 -1.0194"/>
      <geometry>
        <mesh filename="package://ur16e_description/meshes/wrist_1_link.STL"/>
      </geometry>
      <material name="chisel_">
        <color rgba="0 0.5 0.5 1"/>
      </material>
    </visual>
    <collision>
      <origin rpy="0 0 0" xyz="0 -0.0388 -1.0194"/>
      <geometry>
        <mesh filename="package://ur16e_description/meshes/wrist_1_link.STL"/>
      </geometry>
    </collision>
  </link>
  <joint name="chisel_wrist_1_joint" type="revolute">
    <origin rpy="0 1.5708 0" xyz="0 0 0.36"/>
    <!-- edited to fix 0 deg config, was 0 0 0  -->
    <parent link="chisel_forearm_link"/>
    <child link="chisel_wrist_1_link"/>
    <axis xyz="0 1 0"/>
    <limit effort="150.0" lower="-6.28" upper="6.28" velocity="3.14"/>
  </joint>
  <link name="chisel_wrist_2_link">
    <inertial>
      <origin rpy="0 0 0" xyz="4.6306E-08 0.0012823 0.1101"/>
      <mass value="2.3235"/>
      <inertia ixx="0.0039588" ixy="6.2628E-09" ixz="1.2947E-09" iyy="0.003065" iyz="-8.5307E-05" izz="0.0033836"/>
    </inertial>
    <visual>
      <origin rpy="0 0 0" xyz="0 -0.17415 -1.0194"/>
      <geometry>
        <mesh filename="package://ur16e_description/meshes/wrist_2_link.STL"/>
      </geometry>
      <material name="chisel_">
        <color rgba="0.5 0.5 0.5 1"/>
      </material>
    </visual>
    <collision>
      <origin rpy="0 0 0" xyz="0 -0.17415 -1.0194"/>
      <geometry>
        <mesh filename="package://ur16e_description/meshes/wrist_2_link.STL"/>
      </geometry>
    </collision>
  </link>
  <joint name="chisel_wrist_2_joint" type="revolute">
    <origin rpy="0 0 0" xyz="0 0.13535 0"/>
    <parent link="chisel_wrist_1_link"/>
    <child link="chisel_wrist_2_link"/>
    <axis xyz="0 0 1"/>
    <limit effort="150.0" lower="-6.28" upper="6.28" velocity="3.14"/>
  </joint>
  <link name="chisel_wrist_3_link">
    <inertial>
      <origin rpy="0 0 0" xyz="-6.798E-19 0.086857 -2.2204E-16"/>
      <mass value="1.0362"/>
      <inertia ixx="0.0008397" ixy="1.6187E-21" ixz="-4.4721E-35" iyy="0.0010531" iyz="-5.841E-19" izz="0.0008397"/>
    </inertial>
    <visual>
      <origin rpy="0 0 0" xyz="0 -0.17415 -1.13895"/>
      <geometry>
        <mesh filename="package://ur16e_description/meshes/wrist_3_link.STL"/>
      </geometry>
      <material name="chisel_">
        <color rgba="0 0.5 0.5 1"/>
      </material>
    </visual>
    <collision>
      <origin rpy="0 0 0" xyz="0 -0.17415 -1.13895"/>
      <geometry>
        <mesh filename="package://ur16e_description/meshes/wrist_3_link.STL"/>
      </geometry>
    </collision>
  </link>
  <joint name="chisel_wrist_3_joint" type="revolute">
    <origin rpy="0 0 0" xyz="0 0 0.11955"/>
    <parent link="chisel_wrist_2_link"/>
    <child link="chisel_wrist_3_link"/>
    <axis xyz="0 1 0"/>
    <limit effort="150.0" lower="-6.28" upper="6.28" velocity="3.14"/>
  </joint>
  <link name="chisel_dummy_sensor_link">
    <inertial>
      <origin rpy="0 0 0" xyz="0 -0.01875 0"/>
      <mass value="0.16567"/>
      <inertia ixx="7.7658E-05" ixy="-3.0306E-37" ixz="6.3554E-37" iyy="0.00011649" iyz="0" izz="7.7658E-05"/>
    </inertial>
    <visual>
      <origin rpy="0 0 0" xyz="0 -0.32865 -1.13895"/>
      <geometry>
        <mesh filename="package://ur16e_description/meshes/dummy_sensor_link.STL"/>
      </geometry>
      <material name="chisel_">
        <color rgba="0.7 0 0 1"/>
      </material>
    </visual>
    <collision>
      <origin rpy="0 0 0" xyz="0 -0.32865 -1.13895"/>
      <geometry>
        <mesh filename="package://ur16e_description/meshes/dummy_sensor_link.STL"/>
      </geometry>
    </collision>
  </link>
  <joint name="chisel_sensor_mount_fixed" type="fixed">
    <origin rpy="0 0 0" xyz="0 0.1545 0"/>
    <parent link="chisel_wrist_3_link"/>
    <child link="chisel_dummy_sensor_link"/>
    <axis xyz="0 1 0"/>
  </joint>
  <link name="chisel_tool0">
    <inertial>
      <origin rpy="0 0 0" xyz="0 -0.01875 0"/>
      <mass value="0.1"/>
      <inertia ixx="1.1E-05" ixy="-3.0306E-37" ixz="6.3554E-37" iyy="1.1E-05" iyz="0" izz="1.1E-05"/>
    </inertial>
  </link>
  <joint name="chisel_wrist_3_link-tool0_fixed_joint" type="fixed">
    <origin rpy="-1.57079632679 0 0" xyz="0 0.1545 0"/>
    <parent link="chisel_wrist_3_link"/>
    <child link="chisel_tool0"/>
  </joint>
  <transmission name="chisel_shoulder_pan_trans">
    <type>transmission_interface/SimpleTransmission</type>
    <joint name="chisel_shoulder_pan_joint">
      <hardwareInterface>hardware_interface/PositionJointInterface</hardwareInterface>
    </joint>
    <actuator name="chisel_shoulder_pan_motor">
      <mechanicalReduction>1</mechanicalReduction>
    </actuator>
  </transmission>
  <transmission name="chisel_shoulder_lift_trans">
    <type>transmission_interface/SimpleTransmission</type>
    <joint name="chisel_shoulder_lift_joint">
      <hardwareInterface>hardware_interface/PositionJointInterface</hardwareInterface>
    </joint>
    <actuator name="chisel_shoulder_lift_motor">
      <mechanicalReduction>1</mechanicalReduction>
    </actuator>
  </transmission>
  <transmission name="chisel_elbow_trans">
    <type>transmission_interface/SimpleTransmission</type>
    <joint name="chisel_elbow_joint">
      <hardwareInterface>hardware_interface/PositionJointInterface</hardwareInterface>
    </joint>
    <actuator name="chisel_elbow_motor">
      <mechanicalReduction>1</mechanicalReduction>
    </actuator>
  </transmission>
  <transmission name="chisel_wrist_1_trans">
    <type>transmission_interface/SimpleTransmission</type>
    <joint name="chisel_wrist_1_joint">
      <hardwareInterface>hardware_interface/PositionJointInterface</hardwareInterface>
    </joint>
    <actuator name="chisel_wrist_1_motor">
      <mechanicalReduction>1</mechanicalReduction>
    </actuator>
  </transmission>
  <transmission name="chisel_wrist_2_trans">
    <type>transmission_interface/SimpleTransmission</type>
    <joint name="chisel_wrist_2_joint">
      <hardwareInterface>hardware_interface/PositionJointInterface</hardwareInterface>
    </joint>
    <actuator name="chisel_wrist_2_motor">
      <mechanicalReduction>1</mechanicalReduction>
    </actuator>
  </transmission>
  <transmission name="chisel_wrist_3_trans">
    <type>transmission_interface/SimpleTransmission</type>
    <joint name="chisel_wrist_3_joint">
      <hardwareInterface>hardware_interface/PositionJointInterface</hardwareInterface>
    </joint>
    <actuator name="chisel_wrist_3_motor">
      <mechanicalReduction>1</mechanicalReduction>
    </actuator>
  </transmission>
  <gazebo reference="chisel_shoulder_link">
    <selfCollide>true</selfCollide>
  </gazebo>
  <gazebo reference="chisel_upper_arm_link">
    <selfCollide>true</selfCollide>
  </gazebo>
  <gazebo reference="chisel_forearm_link">
    <selfCollide>true</selfCollide>
  </gazebo>
  <gazebo reference="chisel_wrist_1_link">
    <selfCollide>true</selfCollide>
  </gazebo>
  <gazebo reference="chisel_wrist_3_link">
    <selfCollide>true</selfCollide>
  </gazebo>
  <gazebo reference="chisel_wrist_2_link">
    <selfCollide>true</selfCollide>
  </gazebo>
  <gazebo reference="chisel_ee_link">
    <selfCollide>true</selfCollide>
  </gazebo>
  <!-- ROS base_link to UR 'Base' Coordinates transform -->
  <link name="chisel_base"/>
  <joint name="chisel_base_link-base_fixed_joint" type="fixed">
    <!-- NOTE: this rotation is only needed as long as base_link itself is
                not corrected wrt the real robot (ie: rotated over 180
                degrees)
    -->
    <origin rpy="0.0 1.5707963267948966 0.0" xyz="0 0 0"/>
     
    &quot;3.14 -1.5707963267948966 0.0&quot;/
    
    <parent link="chisel_base"/>
    <child link="chisel_base_link"/>
  </joint>
  <!-- attach to tool0  directions: z-pointed towards tool tip, y is "up", x is "out"-->
  <!-- <joint name="chisel_makita_fixed_joint" type="fixed">
    <parent link="chisel_tool0"/>
    <child link="chisel_makita_link"/> -->
    <!-- <origin xyz="0.0 0.0 0.0" rpy="1.57 0.0 3.14" /> -->
  <!-- </joint> -->
  <!-- <link name="chisel_makita_link">
    <visual name="visual">
      <geometry>
        <mesh filename="package://bot_digger_description/meshes/20210408Bosch_top45camera.STL"/>
      </geometry>
      <origin rpy="0.0 0 0.0" xyz="0 0.0 0.0"/>
    </visual>
    <collision>
      <geometry>
        <mesh filename="package://bot_digger_description/meshes/20210408Bosch_top45camera.STL"/>
      </geometry>
      <origin rpy="0.0 0 0.0" xyz="0.0 0.0 0.0"/>
    </collision>
  </link> -->
  <joint name="chisel_chisel_fixed_joint" type="fixed">
    <parent link="chisel_tool0"/>
    <child link="chisel_chisel_link"/>
    <origin rpy="0.0 0.0 1.57" xyz="0.0 0.0 0.54"/>
  </joint>
  <link name="chisel_chisel_link">
    <visual name="visual">
      <geometry>
        <cylinder length="0.28" radius="0.015"/>
      </geometry>
      <material name="LightGrey">
        <color rgba="0.7 0.7 0.7 1.0"/>
      </material>
      <origin rpy="0 0 0" xyz="0 0 0.12"/>
    </visual>
    <collision>
      <geometry>
        <cylinder length="0.28" radius="0.015"/>
      </geometry>
      <origin rpy="0 0 0" xyz="0 0 0.12"/>
    </collision>
    <inertial>
      <mass value="1.0"/>
      <origin rpy="0 0 0" xyz="0.0 0.0 0.12"/>
      <inertia ixx="0.0048562480575" ixy="0.0" ixz="0.0" iyy="0.0048562480575" iyz="0.0" izz="0.0001125"/>
    </inertial>
  </link>
  <!-- <joint name="chisel_tip_fixed_joint" type="fixed">
    <parent link="chisel_tool0"/>
    <child link="chisel_tip_link"/>
    <origin rpy="0.0 0.0 -0.897" xyz="-0.006 0.001 0.811"/>
  </joint> -->
  <!-- frame directions: z along rotation axis, x out top of drill, y out side of drill -->
  <!-- <link name="chisel_tip_link">
    <collision>
      <geometry>
        <box size="0.01 0.01 0.01"/>
      </geometry>
      <origin rpy="0 0 0" xyz="0 0 -0.01"/>
    </collision>
  </link> -->
  <!-- </xacro:macro> -->
</robot>

